The following values were not passed to `accelerate launch` and had defaults used instead:
	`--num_processes` was set to a value of `4`
		More than one GPU was found, enabling multi-GPU training.
		If this was unintended please pass in `--num_processes=1`.
	`--num_machines` was set to a value of `1`
	`--mixed_precision` was set to a value of `'no'`
	`--dynamo_backend` was set to a value of `'no'`
To avoid this warning pass in values for each of the problematic parameters or run `accelerate config`.
/mnt/petrelfs/zhaoshitian/anaconda3/envs/xlab/lib/python3.10/site-packages/accelerate/accelerator.py:443: UserWarning: `log_with=wandb` was passed but no supported trackers are currently installed.
  warnings.warn(f"`log_with={log_with}` was passed but no supported trackers are currently installed.")
Detected kernel version 3.10.0, which is below the recommended minimum of 5.5.0; this can cause the process to hang. It is recommended to upgrade the kernel to the minimum version or higher.
11/20/2024 14:05:42 - INFO - __main__ - Distributed environment: MULTI_GPU  Backend: nccl
Num processes: 4
Process index: 0
Local process index: 0
Device: cuda:0

Mixed precision type: bf16

DEVICE cuda:0
DEVICE cuda:1
/mnt/petrelfs/zhaoshitian/anaconda3/envs/xlab/lib/python3.10/site-packages/accelerate/accelerator.py:443: UserWarning: `log_with=wandb` was passed but no supported trackers are currently installed.
  warnings.warn(f"`log_with={log_with}` was passed but no supported trackers are currently installed.")
11/20/2024 14:05:44 - INFO - __main__ - Distributed environment: MULTI_GPU  Backend: nccl
Num processes: 4
Process index: 1
Local process index: 1
Device: cuda:1

Mixed precision type: bf16

/mnt/petrelfs/zhaoshitian/anaconda3/envs/xlab/lib/python3.10/site-packages/accelerate/accelerator.py:443: UserWarning: `log_with=wandb` was passed but no supported trackers are currently installed.
  warnings.warn(f"`log_with={log_with}` was passed but no supported trackers are currently installed.")
11/20/2024 14:05:44 - INFO - __main__ - Distributed environment: MULTI_GPU  Backend: nccl
Num processes: 4
Process index: 2
Local process index: 2
Device: cuda:2

Mixed precision type: bf16

DEVICE cuda:2
/mnt/petrelfs/zhaoshitian/anaconda3/envs/xlab/lib/python3.10/site-packages/accelerate/accelerator.py:443: UserWarning: `log_with=wandb` was passed but no supported trackers are currently installed.
  warnings.warn(f"`log_with={log_with}` was passed but no supported trackers are currently installed.")
11/20/2024 14:05:44 - INFO - __main__ - Distributed environment: MULTI_GPU  Backend: nccl
Num processes: 4
Process index: 3
Local process index: 3
Device: cuda:3

Mixed precision type: bf16

DEVICE cuda:3
Loading checkpoint shards:   0%|          | 0/2 [00:00<?, ?it/s]Loading checkpoint shards:  50%|█████     | 1/2 [00:01<00:01,  1.10s/it]Loading checkpoint shards: 100%|██████████| 2/2 [00:02<00:00,  1.01it/s]Loading checkpoint shards: 100%|██████████| 2/2 [00:02<00:00,  1.00s/it]
Loading checkpoint shards:   0%|          | 0/2 [00:00<?, ?it/s]Loading checkpoint shards:   0%|          | 0/2 [00:00<?, ?it/s]Loading checkpoint shards:  50%|█████     | 1/2 [00:00<00:00,  3.00it/s]Loading checkpoint shards:  50%|█████     | 1/2 [00:00<00:00,  2.57it/s]Loading checkpoint shards: 100%|██████████| 2/2 [00:00<00:00,  3.21it/s]Loading checkpoint shards: 100%|██████████| 2/2 [00:00<00:00,  3.17it/s]
Loading checkpoint shards:   0%|          | 0/2 [00:00<?, ?it/s]Loading checkpoint shards: 100%|██████████| 2/2 [00:00<00:00,  2.59it/s]Loading checkpoint shards: 100%|██████████| 2/2 [00:00<00:00,  2.59it/s]
Loading checkpoint shards:  50%|█████     | 1/2 [00:00<00:00,  3.21it/s]Loading checkpoint shards: 100%|██████████| 2/2 [00:00<00:00,  3.30it/s]Loading checkpoint shards: 100%|██████████| 2/2 [00:00<00:00,  3.28it/s]
Init model
Init model
Init model
Init model
Loading checkpoint
Loading checkpoint
Loading checkpoint
Loading checkpoint
Init AE
Init AE
Init AE
Init AE
743.80728 parameters
743.80728 parameters
743.80728 parameters
743.80728 parameters
Checkpoint 'latest' does not exist. Starting a new training run.
11/20/2024 14:08:15 - INFO - __main__ - ***** Running training *****
11/20/2024 14:08:15 - INFO - __main__ -   Num Epochs = 9
11/20/2024 14:08:15 - INFO - __main__ -   Instantaneous batch size per device = 3
11/20/2024 14:08:15 - INFO - __main__ -   Total train batch size (w. parallel, distributed & accumulation) = 24
11/20/2024 14:08:15 - INFO - __main__ -   Gradient Accumulation steps = 2
11/20/2024 14:08:15 - INFO - __main__ -   Total optimization steps = 100000
Steps:   0%|          | 0/100000 [00:00<?, ?it/s][rank3]: Traceback (most recent call last):
[rank3]:   File "/mnt/petrelfs/zhaoshitian/anaconda3/envs/xlab/lib/python3.10/site-packages/torch/utils/data/dataloader.py", line 1243, in _try_get_data
[rank3]:     data = self._data_queue.get(timeout=timeout)
[rank3]:   File "/mnt/petrelfs/zhaoshitian/anaconda3/envs/xlab/lib/python3.10/multiprocessing/queues.py", line 113, in get
[rank3]:     if not self._poll(timeout):
[rank3]:   File "/mnt/petrelfs/zhaoshitian/anaconda3/envs/xlab/lib/python3.10/multiprocessing/connection.py", line 262, in poll
[rank3]:     return self._poll(timeout)
[rank3]:   File "/mnt/petrelfs/zhaoshitian/anaconda3/envs/xlab/lib/python3.10/multiprocessing/connection.py", line 429, in _poll
[rank3]:     r = wait([self], timeout)
[rank3]:   File "/mnt/petrelfs/zhaoshitian/anaconda3/envs/xlab/lib/python3.10/multiprocessing/connection.py", line 936, in wait
[rank3]:     ready = selector.select(timeout)
[rank3]:   File "/mnt/petrelfs/zhaoshitian/anaconda3/envs/xlab/lib/python3.10/selectors.py", line 416, in select
[rank3]:     fd_event_list = self._selector.poll(timeout)
[rank3]:   File "/mnt/petrelfs/zhaoshitian/anaconda3/envs/xlab/lib/python3.10/site-packages/torch/utils/data/_utils/signal_handling.py", line 73, in handler
[rank3]:     _error_if_any_worker_fails()
[rank3]: RuntimeError: DataLoader worker (pid 395576) is killed by signal: Killed. 

[rank3]: The above exception was the direct cause of the following exception:

[rank3]: Traceback (most recent call last):
[rank3]:   File "/mnt/petrelfs/zhaoshitian/x-flux-forge/train_flux_deepspeed_controlnet.py", line 317, in <module>
[rank3]:     main()
[rank3]:   File "/mnt/petrelfs/zhaoshitian/x-flux-forge/train_flux_deepspeed_controlnet.py", line 209, in main
[rank3]:     for step, batch in enumerate(train_dataloader):
[rank3]:   File "/mnt/petrelfs/zhaoshitian/anaconda3/envs/xlab/lib/python3.10/site-packages/torch/utils/data/dataloader.py", line 701, in __next__
[rank3]:     data = self._next_data()
[rank3]:   File "/mnt/petrelfs/zhaoshitian/anaconda3/envs/xlab/lib/python3.10/site-packages/torch/utils/data/dataloader.py", line 1448, in _next_data
[rank3]:     idx, data = self._get_data()
[rank3]:   File "/mnt/petrelfs/zhaoshitian/anaconda3/envs/xlab/lib/python3.10/site-packages/torch/utils/data/dataloader.py", line 1412, in _get_data
[rank3]:     success, data = self._try_get_data()
[rank3]:   File "/mnt/petrelfs/zhaoshitian/anaconda3/envs/xlab/lib/python3.10/site-packages/torch/utils/data/dataloader.py", line 1256, in _try_get_data
[rank3]:     raise RuntimeError(
[rank3]: RuntimeError: DataLoader worker (pid(s) 395576) exited unexpectedly
W1120 14:11:40.847520 380326 site-packages/torch/distributed/elastic/multiprocessing/api.py:897] Sending process 382995 closing signal SIGTERM
W1120 14:11:40.851431 380326 site-packages/torch/distributed/elastic/multiprocessing/api.py:897] Sending process 383000 closing signal SIGTERM
W1120 14:11:40.854231 380326 site-packages/torch/distributed/elastic/multiprocessing/api.py:897] Sending process 383009 closing signal SIGTERM
E1120 14:11:41.388380 380326 site-packages/torch/distributed/elastic/multiprocessing/api.py:869] failed (exitcode: 1) local_rank: 3 (pid: 383028) of binary: /mnt/petrelfs/zhaoshitian/anaconda3/envs/xlab/bin/python
Traceback (most recent call last):
  File "/mnt/petrelfs/zhaoshitian/anaconda3/envs/xlab/bin/accelerate", line 8, in <module>
    sys.exit(main())
  File "/mnt/petrelfs/zhaoshitian/anaconda3/envs/xlab/lib/python3.10/site-packages/accelerate/commands/accelerate_cli.py", line 48, in main
    args.func(args)
  File "/mnt/petrelfs/zhaoshitian/anaconda3/envs/xlab/lib/python3.10/site-packages/accelerate/commands/launch.py", line 1159, in launch_command
    multi_gpu_launcher(args)
  File "/mnt/petrelfs/zhaoshitian/anaconda3/envs/xlab/lib/python3.10/site-packages/accelerate/commands/launch.py", line 793, in multi_gpu_launcher
    distrib_run.run(args)
  File "/mnt/petrelfs/zhaoshitian/anaconda3/envs/xlab/lib/python3.10/site-packages/torch/distributed/run.py", line 910, in run
    elastic_launch(
  File "/mnt/petrelfs/zhaoshitian/anaconda3/envs/xlab/lib/python3.10/site-packages/torch/distributed/launcher/api.py", line 138, in __call__
    return launch_agent(self._config, self._entrypoint, list(args))
  File "/mnt/petrelfs/zhaoshitian/anaconda3/envs/xlab/lib/python3.10/site-packages/torch/distributed/launcher/api.py", line 269, in launch_agent
    raise ChildFailedError(
torch.distributed.elastic.multiprocessing.errors.ChildFailedError: 
============================================================
train_flux_deepspeed_controlnet.py FAILED
------------------------------------------------------------
Failures:
  <NO_OTHER_FAILURES>
------------------------------------------------------------
Root Cause (first observed failure):
[0]:
  time      : 2024-11-20_14:11:40
  host      : SH-IDC1-10-140-0-145
  rank      : 3 (local_rank: 3)
  exitcode  : 1 (pid: 383028)
  error_file: <N/A>
  traceback : To enable traceback see: https://pytorch.org/docs/stable/elastic/errors.html
============================================================
srun: error: SH-IDC1-10-140-0-145: task 0: Exited with exit code 1
