The following values were not passed to `accelerate launch` and had defaults used instead:
	`--num_processes` was set to a value of `4`
		More than one GPU was found, enabling multi-GPU training.
		If this was unintended please pass in `--num_processes=1`.
	`--num_machines` was set to a value of `1`
	`--mixed_precision` was set to a value of `'no'`
	`--dynamo_backend` was set to a value of `'no'`
To avoid this warning pass in values for each of the problematic parameters or run `accelerate config`.
/mnt/petrelfs/zhaoshitian/anaconda3/envs/xlab/lib/python3.10/site-packages/accelerate/accelerator.py:443: UserWarning: `log_with=wandb` was passed but no supported trackers are currently installed.
  warnings.warn(f"`log_with={log_with}` was passed but no supported trackers are currently installed.")
Detected kernel version 3.10.0, which is below the recommended minimum of 5.5.0; this can cause the process to hang. It is recommended to upgrade the kernel to the minimum version or higher.
11/20/2024 15:53:28 - INFO - __main__ - Distributed environment: MULTI_GPU  Backend: nccl
Num processes: 4
Process index: 0
Local process index: 0
Device: cuda:0

Mixed precision type: bf16

DEVICE cuda:0
/mnt/petrelfs/zhaoshitian/anaconda3/envs/xlab/lib/python3.10/site-packages/accelerate/accelerator.py:443: UserWarning: `log_with=wandb` was passed but no supported trackers are currently installed.
  warnings.warn(f"`log_with={log_with}` was passed but no supported trackers are currently installed.")
11/20/2024 15:53:30 - INFO - __main__ - Distributed environment: MULTI_GPU  Backend: nccl
Num processes: 4
Process index: 1
Local process index: 1
Device: cuda:1

Mixed precision type: bf16

DEVICE cuda:1
/mnt/petrelfs/zhaoshitian/anaconda3/envs/xlab/lib/python3.10/site-packages/accelerate/accelerator.py:443: UserWarning: `log_with=wandb` was passed but no supported trackers are currently installed.
  warnings.warn(f"`log_with={log_with}` was passed but no supported trackers are currently installed.")
11/20/2024 15:53:30 - INFO - __main__ - Distributed environment: MULTI_GPU  Backend: nccl
Num processes: 4
Process index: 3
Local process index: 3
Device: cuda:3

Mixed precision type: bf16

DEVICE cuda:3
/mnt/petrelfs/zhaoshitian/anaconda3/envs/xlab/lib/python3.10/site-packages/accelerate/accelerator.py:443: UserWarning: `log_with=wandb` was passed but no supported trackers are currently installed.
  warnings.warn(f"`log_with={log_with}` was passed but no supported trackers are currently installed.")
11/20/2024 15:53:30 - INFO - __main__ - Distributed environment: MULTI_GPU  Backend: nccl
Num processes: 4
Process index: 2
Local process index: 2
Device: cuda:2

Mixed precision type: bf16

DEVICE cuda:2
Loading checkpoint shards:   0%|          | 0/2 [00:00<?, ?it/s]Loading checkpoint shards:  50%|█████     | 1/2 [00:00<00:00,  4.79it/s]Loading checkpoint shards: 100%|██████████| 2/2 [00:00<00:00,  5.45it/s]Loading checkpoint shards: 100%|██████████| 2/2 [00:00<00:00,  5.34it/s]
Loading checkpoint shards:   0%|          | 0/2 [00:00<?, ?it/s]Loading checkpoint shards:   0%|          | 0/2 [00:00<?, ?it/s]Loading checkpoint shards:   0%|          | 0/2 [00:00<?, ?it/s]Loading checkpoint shards:  50%|█████     | 1/2 [00:00<00:00,  5.29it/s]Loading checkpoint shards:  50%|█████     | 1/2 [00:00<00:00,  5.31it/s]Loading checkpoint shards:  50%|█████     | 1/2 [00:00<00:00,  5.34it/s]Loading checkpoint shards: 100%|██████████| 2/2 [00:00<00:00,  5.96it/s]Loading checkpoint shards: 100%|██████████| 2/2 [00:00<00:00,  5.85it/s]
Loading checkpoint shards: 100%|██████████| 2/2 [00:00<00:00,  6.01it/s]Loading checkpoint shards: 100%|██████████| 2/2 [00:00<00:00,  5.89it/s]
Loading checkpoint shards: 100%|██████████| 2/2 [00:00<00:00,  5.75it/s]Loading checkpoint shards: 100%|██████████| 2/2 [00:00<00:00,  5.68it/s]
Init model
Init model
Init model
Init model
Loading checkpoint
Loading checkpoint
Loading checkpoint
Loading checkpoint
Init AE
Init AE
Init AE
Init AE
743.80728 parameters
743.80728 parameters
743.80728 parameters
743.80728 parameters
11/20/2024 15:54:15 - INFO - __main__ - ***** Running training *****
11/20/2024 15:54:15 - INFO - __main__ -   Num Epochs = 9
11/20/2024 15:54:15 - INFO - __main__ -   Instantaneous batch size per device = 3
11/20/2024 15:54:15 - INFO - __main__ -   Total train batch size (w. parallel, distributed & accumulation) = 24
11/20/2024 15:54:15 - INFO - __main__ -   Gradient Accumulation steps = 2
11/20/2024 15:54:15 - INFO - __main__ -   Total optimization steps = 100000
Checkpoint 'latest' does not exist. Starting a new training run.
Steps:   0%|          | 0/100000 [00:00<?, ?it/s][rank1]: Traceback (most recent call last):
[rank1]:   File "/mnt/petrelfs/zhaoshitian/anaconda3/envs/xlab/lib/python3.10/site-packages/einops/einops.py", line 523, in reduce
[rank1]:     return _apply_recipe(
[rank1]:   File "/mnt/petrelfs/zhaoshitian/anaconda3/envs/xlab/lib/python3.10/site-packages/einops/einops.py", line 234, in _apply_recipe
[rank1]:     init_shapes, axes_reordering, reduced_axes, added_axes, final_shapes, n_axes_w_added = _reconstruct_from_shape(
[rank1]:   File "/mnt/petrelfs/zhaoshitian/anaconda3/envs/xlab/lib/python3.10/site-packages/einops/einops.py", line 187, in _reconstruct_from_shape_uncached
[rank1]:     raise EinopsError(f"Shape mismatch, can't divide axis of length {length} in chunks of {known_product}")
[rank1]: einops.EinopsError: Shape mismatch, can't divide axis of length 93 in chunks of 2

[rank1]: During handling of the above exception, another exception occurred:

[rank1]: Traceback (most recent call last):
[rank1]:   File "/mnt/petrelfs/zhaoshitian/x-flux-forge/train_flux_deepspeed_controlnet.py", line 318, in <module>
[rank1]:     main()
[rank1]:   File "/mnt/petrelfs/zhaoshitian/x-flux-forge/train_flux_deepspeed_controlnet.py", line 216, in main
[rank1]:     inp = prepare(t5=t5, clip=clip, img=x_1, prompt=prompts)
[rank1]:   File "/mnt/petrelfs/zhaoshitian/x-flux-forge/src/flux/sampling.py", line 39, in prepare
[rank1]:     img = rearrange(img, "b c (h ph) (w pw) -> b (h w) (c ph pw)", ph=2, pw=2)
[rank1]:   File "/mnt/petrelfs/zhaoshitian/anaconda3/envs/xlab/lib/python3.10/site-packages/einops/einops.py", line 591, in rearrange
[rank1]:     return reduce(tensor, pattern, reduction="rearrange", **axes_lengths)
[rank1]:   File "/mnt/petrelfs/zhaoshitian/anaconda3/envs/xlab/lib/python3.10/site-packages/einops/einops.py", line 533, in reduce
[rank1]:     raise EinopsError(message + "\n {}".format(e))
[rank1]: einops.EinopsError:  Error while processing rearrange-reduction pattern "b c (h ph) (w pw) -> b (h w) (c ph pw)".
[rank1]:  Input tensor shape: torch.Size([4, 16, 93, 62]). Additional info: {'ph': 2, 'pw': 2}.
[rank1]:  Shape mismatch, can't divide axis of length 93 in chunks of 2
[rank0]: Traceback (most recent call last):
[rank0]:   File "/mnt/petrelfs/zhaoshitian/anaconda3/envs/xlab/lib/python3.10/site-packages/einops/einops.py", line 523, in reduce
[rank0]:     return _apply_recipe(
[rank0]:   File "/mnt/petrelfs/zhaoshitian/anaconda3/envs/xlab/lib/python3.10/site-packages/einops/einops.py", line 234, in _apply_recipe
[rank0]:     init_shapes, axes_reordering, reduced_axes, added_axes, final_shapes, n_axes_w_added = _reconstruct_from_shape(
[rank0]:   File "/mnt/petrelfs/zhaoshitian/anaconda3/envs/xlab/lib/python3.10/site-packages/einops/einops.py", line 187, in _reconstruct_from_shape_uncached
[rank0]:     raise EinopsError(f"Shape mismatch, can't divide axis of length {length} in chunks of {known_product}")
[rank0]: einops.EinopsError: Shape mismatch, can't divide axis of length 93 in chunks of 2

[rank0]: During handling of the above exception, another exception occurred:

[rank0]: Traceback (most recent call last):
[rank0]:   File "/mnt/petrelfs/zhaoshitian/x-flux-forge/train_flux_deepspeed_controlnet.py", line 318, in <module>
[rank0]:     main()
[rank0]:   File "/mnt/petrelfs/zhaoshitian/x-flux-forge/train_flux_deepspeed_controlnet.py", line 216, in main
[rank0]:     inp = prepare(t5=t5, clip=clip, img=x_1, prompt=prompts)
[rank0]:   File "/mnt/petrelfs/zhaoshitian/x-flux-forge/src/flux/sampling.py", line 39, in prepare
[rank0]:     img = rearrange(img, "b c (h ph) (w pw) -> b (h w) (c ph pw)", ph=2, pw=2)
[rank0]:   File "/mnt/petrelfs/zhaoshitian/anaconda3/envs/xlab/lib/python3.10/site-packages/einops/einops.py", line 591, in rearrange
[rank0]:     return reduce(tensor, pattern, reduction="rearrange", **axes_lengths)
[rank0]:   File "/mnt/petrelfs/zhaoshitian/anaconda3/envs/xlab/lib/python3.10/site-packages/einops/einops.py", line 533, in reduce
[rank0]:     raise EinopsError(message + "\n {}".format(e))
[rank0]: einops.EinopsError:  Error while processing rearrange-reduction pattern "b c (h ph) (w pw) -> b (h w) (c ph pw)".
[rank0]:  Input tensor shape: torch.Size([4, 16, 93, 62]). Additional info: {'ph': 2, 'pw': 2}.
[rank0]:  Shape mismatch, can't divide axis of length 93 in chunks of 2
[rank2]: Traceback (most recent call last):
[rank2]:   File "/mnt/petrelfs/zhaoshitian/anaconda3/envs/xlab/lib/python3.10/site-packages/einops/einops.py", line 523, in reduce
[rank2]:     return _apply_recipe(
[rank2]:   File "/mnt/petrelfs/zhaoshitian/anaconda3/envs/xlab/lib/python3.10/site-packages/einops/einops.py", line 234, in _apply_recipe
[rank2]:     init_shapes, axes_reordering, reduced_axes, added_axes, final_shapes, n_axes_w_added = _reconstruct_from_shape(
[rank2]:   File "/mnt/petrelfs/zhaoshitian/anaconda3/envs/xlab/lib/python3.10/site-packages/einops/einops.py", line 187, in _reconstruct_from_shape_uncached
[rank2]:     raise EinopsError(f"Shape mismatch, can't divide axis of length {length} in chunks of {known_product}")
[rank2]: einops.EinopsError: Shape mismatch, can't divide axis of length 93 in chunks of 2

[rank2]: During handling of the above exception, another exception occurred:

[rank2]: Traceback (most recent call last):
[rank2]:   File "/mnt/petrelfs/zhaoshitian/x-flux-forge/train_flux_deepspeed_controlnet.py", line 318, in <module>
[rank2]:     main()
[rank2]:   File "/mnt/petrelfs/zhaoshitian/x-flux-forge/train_flux_deepspeed_controlnet.py", line 216, in main
[rank2]:     inp = prepare(t5=t5, clip=clip, img=x_1, prompt=prompts)
[rank2]:   File "/mnt/petrelfs/zhaoshitian/x-flux-forge/src/flux/sampling.py", line 39, in prepare
[rank2]:     img = rearrange(img, "b c (h ph) (w pw) -> b (h w) (c ph pw)", ph=2, pw=2)
[rank2]:   File "/mnt/petrelfs/zhaoshitian/anaconda3/envs/xlab/lib/python3.10/site-packages/einops/einops.py", line 591, in rearrange
[rank2]:     return reduce(tensor, pattern, reduction="rearrange", **axes_lengths)
[rank2]:   File "/mnt/petrelfs/zhaoshitian/anaconda3/envs/xlab/lib/python3.10/site-packages/einops/einops.py", line 533, in reduce
[rank2]:     raise EinopsError(message + "\n {}".format(e))
[rank2]: einops.EinopsError:  Error while processing rearrange-reduction pattern "b c (h ph) (w pw) -> b (h w) (c ph pw)".
[rank2]:  Input tensor shape: torch.Size([4, 16, 93, 62]). Additional info: {'ph': 2, 'pw': 2}.
[rank2]:  Shape mismatch, can't divide axis of length 93 in chunks of 2
[rank3]: Traceback (most recent call last):
[rank3]:   File "/mnt/petrelfs/zhaoshitian/anaconda3/envs/xlab/lib/python3.10/site-packages/einops/einops.py", line 523, in reduce
[rank3]:     return _apply_recipe(
[rank3]:   File "/mnt/petrelfs/zhaoshitian/anaconda3/envs/xlab/lib/python3.10/site-packages/einops/einops.py", line 234, in _apply_recipe
[rank3]:     init_shapes, axes_reordering, reduced_axes, added_axes, final_shapes, n_axes_w_added = _reconstruct_from_shape(
[rank3]:   File "/mnt/petrelfs/zhaoshitian/anaconda3/envs/xlab/lib/python3.10/site-packages/einops/einops.py", line 187, in _reconstruct_from_shape_uncached
[rank3]:     raise EinopsError(f"Shape mismatch, can't divide axis of length {length} in chunks of {known_product}")
[rank3]: einops.EinopsError: Shape mismatch, can't divide axis of length 93 in chunks of 2

[rank3]: During handling of the above exception, another exception occurred:

[rank3]: Traceback (most recent call last):
[rank3]:   File "/mnt/petrelfs/zhaoshitian/x-flux-forge/train_flux_deepspeed_controlnet.py", line 318, in <module>
[rank3]:     main()
[rank3]:   File "/mnt/petrelfs/zhaoshitian/x-flux-forge/train_flux_deepspeed_controlnet.py", line 216, in main
[rank3]:     inp = prepare(t5=t5, clip=clip, img=x_1, prompt=prompts)
[rank3]:   File "/mnt/petrelfs/zhaoshitian/x-flux-forge/src/flux/sampling.py", line 39, in prepare
[rank3]:     img = rearrange(img, "b c (h ph) (w pw) -> b (h w) (c ph pw)", ph=2, pw=2)
[rank3]:   File "/mnt/petrelfs/zhaoshitian/anaconda3/envs/xlab/lib/python3.10/site-packages/einops/einops.py", line 591, in rearrange
[rank3]:     return reduce(tensor, pattern, reduction="rearrange", **axes_lengths)
[rank3]:   File "/mnt/petrelfs/zhaoshitian/anaconda3/envs/xlab/lib/python3.10/site-packages/einops/einops.py", line 533, in reduce
[rank3]:     raise EinopsError(message + "\n {}".format(e))
[rank3]: einops.EinopsError:  Error while processing rearrange-reduction pattern "b c (h ph) (w pw) -> b (h w) (c ph pw)".
[rank3]:  Input tensor shape: torch.Size([4, 16, 93, 62]). Additional info: {'ph': 2, 'pw': 2}.
[rank3]:  Shape mismatch, can't divide axis of length 93 in chunks of 2
Steps:   0%|          | 0/100000 [00:03<?, ?it/s]
[rank0]:[W1120 15:54:20.769847594 ProcessGroupNCCL.cpp:1250] Warning: WARNING: process group has NOT been destroyed before we destruct ProcessGroupNCCL. On normal program exit, the application should call destroy_process_group to ensure that any pending NCCL operations have finished in this process. In rare cases this process can exit before this point and block the progress of another member of the process group. This constraint has always been present,  but this warning has only been added since PyTorch 2.4 (function operator())
W1120 15:54:22.065727 34446 site-packages/torch/distributed/elastic/multiprocessing/api.py:897] Sending process 35053 closing signal SIGTERM
W1120 15:54:22.068782 34446 site-packages/torch/distributed/elastic/multiprocessing/api.py:897] Sending process 35054 closing signal SIGTERM
W1120 15:54:22.069315 34446 site-packages/torch/distributed/elastic/multiprocessing/api.py:897] Sending process 35055 closing signal SIGTERM
E1120 15:54:22.360496 34446 site-packages/torch/distributed/elastic/multiprocessing/api.py:869] failed (exitcode: 1) local_rank: 3 (pid: 35056) of binary: /mnt/petrelfs/zhaoshitian/anaconda3/envs/xlab/bin/python
Traceback (most recent call last):
  File "/mnt/petrelfs/zhaoshitian/anaconda3/envs/xlab/bin/accelerate", line 8, in <module>
    sys.exit(main())
  File "/mnt/petrelfs/zhaoshitian/anaconda3/envs/xlab/lib/python3.10/site-packages/accelerate/commands/accelerate_cli.py", line 48, in main
    args.func(args)
  File "/mnt/petrelfs/zhaoshitian/anaconda3/envs/xlab/lib/python3.10/site-packages/accelerate/commands/launch.py", line 1159, in launch_command
    multi_gpu_launcher(args)
  File "/mnt/petrelfs/zhaoshitian/anaconda3/envs/xlab/lib/python3.10/site-packages/accelerate/commands/launch.py", line 793, in multi_gpu_launcher
    distrib_run.run(args)
  File "/mnt/petrelfs/zhaoshitian/anaconda3/envs/xlab/lib/python3.10/site-packages/torch/distributed/run.py", line 910, in run
    elastic_launch(
  File "/mnt/petrelfs/zhaoshitian/anaconda3/envs/xlab/lib/python3.10/site-packages/torch/distributed/launcher/api.py", line 138, in __call__
    return launch_agent(self._config, self._entrypoint, list(args))
  File "/mnt/petrelfs/zhaoshitian/anaconda3/envs/xlab/lib/python3.10/site-packages/torch/distributed/launcher/api.py", line 269, in launch_agent
    raise ChildFailedError(
torch.distributed.elastic.multiprocessing.errors.ChildFailedError: 
============================================================
train_flux_deepspeed_controlnet.py FAILED
------------------------------------------------------------
Failures:
  <NO_OTHER_FAILURES>
------------------------------------------------------------
Root Cause (first observed failure):
[0]:
  time      : 2024-11-20_15:54:22
  host      : SH-IDC1-10-140-0-208
  rank      : 3 (local_rank: 3)
  exitcode  : 1 (pid: 35056)
  error_file: <N/A>
  traceback : To enable traceback see: https://pytorch.org/docs/stable/elastic/errors.html
============================================================
srun: error: SH-IDC1-10-140-0-208: task 0: Exited with exit code 1
