The following values were not passed to `accelerate launch` and had defaults used instead:
	`--num_processes` was set to a value of `4`
		More than one GPU was found, enabling multi-GPU training.
		If this was unintended please pass in `--num_processes=1`.
	`--num_machines` was set to a value of `1`
	`--mixed_precision` was set to a value of `'no'`
	`--dynamo_backend` was set to a value of `'no'`
To avoid this warning pass in values for each of the problematic parameters or run `accelerate config`.
/mnt/petrelfs/zhaoshitian/anaconda3/envs/xlab/lib/python3.10/site-packages/accelerate/accelerator.py:443: UserWarning: `log_with=wandb` was passed but no supported trackers are currently installed.
  warnings.warn(f"`log_with={log_with}` was passed but no supported trackers are currently installed.")
Detected kernel version 3.10.0, which is below the recommended minimum of 5.5.0; this can cause the process to hang. It is recommended to upgrade the kernel to the minimum version or higher.
11/20/2024 18:22:10 - INFO - __main__ - Distributed environment: MULTI_GPU  Backend: nccl
Num processes: 4
Process index: 0
Local process index: 0
Device: cuda:0

Mixed precision type: bf16

DEVICE cuda:0
/mnt/petrelfs/zhaoshitian/anaconda3/envs/xlab/lib/python3.10/site-packages/accelerate/accelerator.py:443: UserWarning: `log_with=wandb` was passed but no supported trackers are currently installed.
  warnings.warn(f"`log_with={log_with}` was passed but no supported trackers are currently installed.")
11/20/2024 18:22:11 - INFO - __main__ - Distributed environment: MULTI_GPU  Backend: nccl
Num processes: 4
Process index: 3
Local process index: 3
Device: cuda:3

Mixed precision type: bf16

/mnt/petrelfs/zhaoshitian/anaconda3/envs/xlab/lib/python3.10/site-packages/accelerate/accelerator.py:443: UserWarning: `log_with=wandb` was passed but no supported trackers are currently installed.
  warnings.warn(f"`log_with={log_with}` was passed but no supported trackers are currently installed.")
DEVICE cuda:3
11/20/2024 18:22:11 - INFO - __main__ - Distributed environment: MULTI_GPU  Backend: nccl
Num processes: 4
Process index: 1
Local process index: 1
Device: cuda:1

Mixed precision type: bf16

DEVICE cuda:1
/mnt/petrelfs/zhaoshitian/anaconda3/envs/xlab/lib/python3.10/site-packages/accelerate/accelerator.py:443: UserWarning: `log_with=wandb` was passed but no supported trackers are currently installed.
  warnings.warn(f"`log_with={log_with}` was passed but no supported trackers are currently installed.")
11/20/2024 18:22:13 - INFO - __main__ - Distributed environment: MULTI_GPU  Backend: nccl
Num processes: 4
Process index: 2
Local process index: 2
Device: cuda:2

Mixed precision type: bf16

DEVICE cuda:2
Loading checkpoint shards:   0%|          | 0/2 [00:00<?, ?it/s]Loading checkpoint shards:  50%|█████     | 1/2 [00:00<00:00,  4.77it/s]Loading checkpoint shards: 100%|██████████| 2/2 [00:00<00:00,  5.55it/s]Loading checkpoint shards: 100%|██████████| 2/2 [00:00<00:00,  5.41it/s]
Loading checkpoint shards:   0%|          | 0/2 [00:00<?, ?it/s]Loading checkpoint shards:   0%|          | 0/2 [00:00<?, ?it/s]Loading checkpoint shards:  50%|█████     | 1/2 [00:00<00:00,  5.57it/s]Loading checkpoint shards:  50%|█████     | 1/2 [00:00<00:00,  5.69it/s]Loading checkpoint shards: 100%|██████████| 2/2 [00:00<00:00,  6.31it/s]Loading checkpoint shards: 100%|██████████| 2/2 [00:00<00:00,  6.19it/s]
Loading checkpoint shards: 100%|██████████| 2/2 [00:00<00:00,  6.44it/s]Loading checkpoint shards: 100%|██████████| 2/2 [00:00<00:00,  6.31it/s]
Loading checkpoint shards:   0%|          | 0/2 [00:00<?, ?it/s]Loading checkpoint shards:  50%|█████     | 1/2 [00:00<00:00,  4.56it/s]Loading checkpoint shards: 100%|██████████| 2/2 [00:00<00:00,  5.70it/s]Loading checkpoint shards: 100%|██████████| 2/2 [00:00<00:00,  5.49it/s]
[rank2]: Traceback (most recent call last):
[rank2]:   File "/mnt/petrelfs/zhaoshitian/x-flux-forge/train_flux_deepspeed_controlnet.py", line 318, in <module>
[rank2]:     main()
[rank2]:   File "/mnt/petrelfs/zhaoshitian/x-flux-forge/train_flux_deepspeed_controlnet.py", line 104, in main
[rank2]:     dit, vae, t5, clip = get_models(name=args.model_name, device=accelerator.device, offload=False, is_schnell=is_schnell)
[rank2]:   File "/mnt/petrelfs/zhaoshitian/x-flux-forge/train_flux_deepspeed_controlnet.py", line 48, in get_models
[rank2]:     t5 = load_t5(device, max_length=256 if is_schnell else 512)
[rank2]:   File "/mnt/petrelfs/zhaoshitian/x-flux-forge/src/flux/util.py", line 365, in load_t5
[rank2]:     return HFEmbedder("/mnt/petrelfs/zhaoshitian/models/xflux_text_encoders", max_length=max_length, torch_dtype=torch.bfloat16, force_download=False).to(device)
[rank2]:   File "/mnt/petrelfs/zhaoshitian/anaconda3/envs/xlab/lib/python3.10/site-packages/torch/nn/modules/module.py", line 1340, in to
[rank2]:     return self._apply(convert)
[rank2]:   File "/mnt/petrelfs/zhaoshitian/anaconda3/envs/xlab/lib/python3.10/site-packages/torch/nn/modules/module.py", line 900, in _apply
[rank2]:     module._apply(fn)
[rank2]:   File "/mnt/petrelfs/zhaoshitian/anaconda3/envs/xlab/lib/python3.10/site-packages/torch/nn/modules/module.py", line 900, in _apply
[rank2]:     module._apply(fn)
[rank2]:   File "/mnt/petrelfs/zhaoshitian/anaconda3/envs/xlab/lib/python3.10/site-packages/torch/nn/modules/module.py", line 900, in _apply
[rank2]:     module._apply(fn)
[rank2]:   [Previous line repeated 5 more times]
[rank2]:   File "/mnt/petrelfs/zhaoshitian/anaconda3/envs/xlab/lib/python3.10/site-packages/torch/nn/modules/module.py", line 927, in _apply
[rank2]:     param_applied = fn(param)
[rank2]:   File "/mnt/petrelfs/zhaoshitian/anaconda3/envs/xlab/lib/python3.10/site-packages/torch/nn/modules/module.py", line 1326, in convert
[rank2]:     return t.to(
[rank2]: torch.OutOfMemoryError: CUDA out of memory. Tried to allocate 32.00 MiB. GPU 2 has a total capacity of 79.32 GiB of which 27.56 MiB is free. Process 58425 has 74.79 GiB memory in use. Including non-PyTorch memory, this process has 4.50 GiB memory in use. Of the allocated memory 3.51 GiB is allocated by PyTorch, and 1.86 MiB is reserved by PyTorch but unallocated. If reserved but unallocated memory is large try setting PYTORCH_CUDA_ALLOC_CONF=expandable_segments:True to avoid fragmentation.  See documentation for Memory Management  (https://pytorch.org/docs/stable/notes/cuda.html#environment-variables)
W1120 18:22:21.607695 433239 site-packages/torch/distributed/elastic/multiprocessing/api.py:897] Sending process 433333 closing signal SIGTERM
W1120 18:22:21.610542 433239 site-packages/torch/distributed/elastic/multiprocessing/api.py:897] Sending process 433334 closing signal SIGTERM
W1120 18:22:21.611035 433239 site-packages/torch/distributed/elastic/multiprocessing/api.py:897] Sending process 433336 closing signal SIGTERM
E1120 18:22:22.138869 433239 site-packages/torch/distributed/elastic/multiprocessing/api.py:869] failed (exitcode: 1) local_rank: 2 (pid: 433335) of binary: /mnt/petrelfs/zhaoshitian/anaconda3/envs/xlab/bin/python
Traceback (most recent call last):
  File "/mnt/petrelfs/zhaoshitian/anaconda3/envs/xlab/bin/accelerate", line 8, in <module>
    sys.exit(main())
  File "/mnt/petrelfs/zhaoshitian/anaconda3/envs/xlab/lib/python3.10/site-packages/accelerate/commands/accelerate_cli.py", line 48, in main
    args.func(args)
  File "/mnt/petrelfs/zhaoshitian/anaconda3/envs/xlab/lib/python3.10/site-packages/accelerate/commands/launch.py", line 1159, in launch_command
    multi_gpu_launcher(args)
  File "/mnt/petrelfs/zhaoshitian/anaconda3/envs/xlab/lib/python3.10/site-packages/accelerate/commands/launch.py", line 793, in multi_gpu_launcher
    distrib_run.run(args)
  File "/mnt/petrelfs/zhaoshitian/anaconda3/envs/xlab/lib/python3.10/site-packages/torch/distributed/run.py", line 910, in run
    elastic_launch(
  File "/mnt/petrelfs/zhaoshitian/anaconda3/envs/xlab/lib/python3.10/site-packages/torch/distributed/launcher/api.py", line 138, in __call__
    return launch_agent(self._config, self._entrypoint, list(args))
  File "/mnt/petrelfs/zhaoshitian/anaconda3/envs/xlab/lib/python3.10/site-packages/torch/distributed/launcher/api.py", line 269, in launch_agent
    raise ChildFailedError(
torch.distributed.elastic.multiprocessing.errors.ChildFailedError: 
============================================================
train_flux_deepspeed_controlnet.py FAILED
------------------------------------------------------------
Failures:
  <NO_OTHER_FAILURES>
------------------------------------------------------------
Root Cause (first observed failure):
[0]:
  time      : 2024-11-20_18:22:21
  host      : SH-IDC1-10-140-1-64
  rank      : 2 (local_rank: 2)
  exitcode  : 1 (pid: 433335)
  error_file: <N/A>
  traceback : To enable traceback see: https://pytorch.org/docs/stable/elastic/errors.html
============================================================
srun: error: SH-IDC1-10-140-1-64: task 0: Exited with exit code 1
