The following values were not passed to `accelerate launch` and had defaults used instead:
	`--num_processes` was set to a value of `4`
		More than one GPU was found, enabling multi-GPU training.
		If this was unintended please pass in `--num_processes=1`.
	`--num_machines` was set to a value of `1`
	`--mixed_precision` was set to a value of `'no'`
	`--dynamo_backend` was set to a value of `'no'`
To avoid this warning pass in values for each of the problematic parameters or run `accelerate config`.
/mnt/petrelfs/zhaoshitian/anaconda3/envs/xlab/lib/python3.10/site-packages/accelerate/accelerator.py:443: UserWarning: `log_with=wandb` was passed but no supported trackers are currently installed.
  warnings.warn(f"`log_with={log_with}` was passed but no supported trackers are currently installed.")
Detected kernel version 3.10.0, which is below the recommended minimum of 5.5.0; this can cause the process to hang. It is recommended to upgrade the kernel to the minimum version or higher.
11/20/2024 15:50:06 - INFO - __main__ - Distributed environment: MULTI_GPU  Backend: nccl
Num processes: 4
Process index: 0
Local process index: 0
Device: cuda:0

Mixed precision type: bf16

DEVICE cuda:0
/mnt/petrelfs/zhaoshitian/anaconda3/envs/xlab/lib/python3.10/site-packages/accelerate/accelerator.py:443: UserWarning: `log_with=wandb` was passed but no supported trackers are currently installed.
  warnings.warn(f"`log_with={log_with}` was passed but no supported trackers are currently installed.")
11/20/2024 15:50:07 - INFO - __main__ - Distributed environment: MULTI_GPU  Backend: nccl
Num processes: 4
Process index: 2
Local process index: 2
Device: cuda:2

Mixed precision type: bf16

DEVICE cuda:2
/mnt/petrelfs/zhaoshitian/anaconda3/envs/xlab/lib/python3.10/site-packages/accelerate/accelerator.py:443: UserWarning: `log_with=wandb` was passed but no supported trackers are currently installed.
  warnings.warn(f"`log_with={log_with}` was passed but no supported trackers are currently installed.")
11/20/2024 15:50:07 - INFO - __main__ - Distributed environment: MULTI_GPU  Backend: nccl
Num processes: 4
Process index: 3
Local process index: 3
Device: cuda:3

Mixed precision type: bf16

DEVICE cuda:3
/mnt/petrelfs/zhaoshitian/anaconda3/envs/xlab/lib/python3.10/site-packages/accelerate/accelerator.py:443: UserWarning: `log_with=wandb` was passed but no supported trackers are currently installed.
  warnings.warn(f"`log_with={log_with}` was passed but no supported trackers are currently installed.")
11/20/2024 15:50:07 - INFO - __main__ - Distributed environment: MULTI_GPU  Backend: nccl
Num processes: 4
Process index: 1
Local process index: 1
Device: cuda:1

Mixed precision type: bf16

DEVICE cuda:1
Loading checkpoint shards:   0%|          | 0/2 [00:00<?, ?it/s]Loading checkpoint shards:  50%|█████     | 1/2 [00:00<00:00,  3.81it/s]Loading checkpoint shards: 100%|██████████| 2/2 [00:00<00:00,  4.30it/s]Loading checkpoint shards: 100%|██████████| 2/2 [00:00<00:00,  4.21it/s]
Loading checkpoint shards:   0%|          | 0/2 [00:00<?, ?it/s]Loading checkpoint shards:   0%|          | 0/2 [00:00<?, ?it/s]Loading checkpoint shards:   0%|          | 0/2 [00:00<?, ?it/s]Loading checkpoint shards:  50%|█████     | 1/2 [00:00<00:00,  5.01it/s]Loading checkpoint shards:  50%|█████     | 1/2 [00:00<00:00,  5.05it/s]Loading checkpoint shards:  50%|█████     | 1/2 [00:00<00:00,  4.94it/s]Loading checkpoint shards: 100%|██████████| 2/2 [00:00<00:00,  5.68it/s]Loading checkpoint shards: 100%|██████████| 2/2 [00:00<00:00,  5.58it/s]
Loading checkpoint shards: 100%|██████████| 2/2 [00:00<00:00,  4.94it/s]Loading checkpoint shards: 100%|██████████| 2/2 [00:00<00:00,  4.95it/s]
Loading checkpoint shards: 100%|██████████| 2/2 [00:00<00:00,  5.58it/s]Loading checkpoint shards: 100%|██████████| 2/2 [00:00<00:00,  5.47it/s]
Init model
Init model
Init model
Init model
Loading checkpoint
Loading checkpoint
Loading checkpoint
Loading checkpoint
Init AE
Init AE
Init AE
Init AE
743.80728 parameters
[rank0]: Traceback (most recent call last):
[rank0]:   File "/mnt/petrelfs/zhaoshitian/x-flux-forge/train_flux_deepspeed_controlnet.py", line 318, in <module>
[rank0]:     main()
[rank0]:   File "/mnt/petrelfs/zhaoshitian/x-flux-forge/train_flux_deepspeed_controlnet.py", line 127, in main
[rank0]:     train_dataloader = loader(**args.data_config)
[rank0]:   File "/mnt/petrelfs/zhaoshitian/x-flux-forge/image_datasets/controlnet_dataset.py", line 128, in loader
[rank0]:     dataset = CustomImageDataset(**args)
[rank0]:   File "/mnt/petrelfs/zhaoshitian/x-flux-forge/image_datasets/controlnet_dataset.py", line 100, in __init__
[rank0]:     self.data_list = json.load(open(data_file_path, "r"))
[rank0]: IsADirectoryError: [Errno 21] Is a directory: '/mnt/petrelfs/zhaoshitian/data/movie_posters_100k_controlnet/data'
[rank0]:[W1120 15:51:09.105916548 ProcessGroupNCCL.cpp:1250] Warning: WARNING: process group has NOT been destroyed before we destruct ProcessGroupNCCL. On normal program exit, the application should call destroy_process_group to ensure that any pending NCCL operations have finished in this process. In rare cases this process can exit before this point and block the progress of another member of the process group. This constraint has always been present,  but this warning has only been added since PyTorch 2.4 (function operator())
743.80728 parameters
743.80728 parameters
[rank3]: Traceback (most recent call last):
[rank3]:   File "/mnt/petrelfs/zhaoshitian/x-flux-forge/train_flux_deepspeed_controlnet.py", line 318, in <module>
[rank3]:     main()
[rank3]:   File "/mnt/petrelfs/zhaoshitian/x-flux-forge/train_flux_deepspeed_controlnet.py", line 127, in main
[rank3]:     train_dataloader = loader(**args.data_config)
[rank3]:   File "/mnt/petrelfs/zhaoshitian/x-flux-forge/image_datasets/controlnet_dataset.py", line 128, in loader
[rank3]:     dataset = CustomImageDataset(**args)
[rank3]:   File "/mnt/petrelfs/zhaoshitian/x-flux-forge/image_datasets/controlnet_dataset.py", line 100, in __init__
[rank3]:     self.data_list = json.load(open(data_file_path, "r"))
[rank3]: IsADirectoryError: [Errno 21] Is a directory: '/mnt/petrelfs/zhaoshitian/data/movie_posters_100k_controlnet/data'
[rank2]: Traceback (most recent call last):
[rank2]:   File "/mnt/petrelfs/zhaoshitian/x-flux-forge/train_flux_deepspeed_controlnet.py", line 318, in <module>
[rank2]:     main()
[rank2]:   File "/mnt/petrelfs/zhaoshitian/x-flux-forge/train_flux_deepspeed_controlnet.py", line 127, in main
[rank2]:     train_dataloader = loader(**args.data_config)
[rank2]:   File "/mnt/petrelfs/zhaoshitian/x-flux-forge/image_datasets/controlnet_dataset.py", line 128, in loader
[rank2]:     dataset = CustomImageDataset(**args)
[rank2]:   File "/mnt/petrelfs/zhaoshitian/x-flux-forge/image_datasets/controlnet_dataset.py", line 100, in __init__
[rank2]:     self.data_list = json.load(open(data_file_path, "r"))
[rank2]: IsADirectoryError: [Errno 21] Is a directory: '/mnt/petrelfs/zhaoshitian/data/movie_posters_100k_controlnet/data'
743.80728 parameters
[rank1]: Traceback (most recent call last):
[rank1]:   File "/mnt/petrelfs/zhaoshitian/x-flux-forge/train_flux_deepspeed_controlnet.py", line 318, in <module>
[rank1]:     main()
[rank1]:   File "/mnt/petrelfs/zhaoshitian/x-flux-forge/train_flux_deepspeed_controlnet.py", line 127, in main
[rank1]:     train_dataloader = loader(**args.data_config)
[rank1]:   File "/mnt/petrelfs/zhaoshitian/x-flux-forge/image_datasets/controlnet_dataset.py", line 128, in loader
[rank1]:     dataset = CustomImageDataset(**args)
[rank1]:   File "/mnt/petrelfs/zhaoshitian/x-flux-forge/image_datasets/controlnet_dataset.py", line 100, in __init__
[rank1]:     self.data_list = json.load(open(data_file_path, "r"))
[rank1]: IsADirectoryError: [Errno 21] Is a directory: '/mnt/petrelfs/zhaoshitian/data/movie_posters_100k_controlnet/data'
W1120 15:51:10.877462 84249 site-packages/torch/distributed/elastic/multiprocessing/api.py:897] Sending process 84444 closing signal SIGTERM
W1120 15:51:10.880701 84249 site-packages/torch/distributed/elastic/multiprocessing/api.py:897] Sending process 84445 closing signal SIGTERM
W1120 15:51:10.881255 84249 site-packages/torch/distributed/elastic/multiprocessing/api.py:897] Sending process 84447 closing signal SIGTERM
E1120 15:51:11.496068 84249 site-packages/torch/distributed/elastic/multiprocessing/api.py:869] failed (exitcode: 1) local_rank: 0 (pid: 84443) of binary: /mnt/petrelfs/zhaoshitian/anaconda3/envs/xlab/bin/python
Traceback (most recent call last):
  File "/mnt/petrelfs/zhaoshitian/anaconda3/envs/xlab/bin/accelerate", line 8, in <module>
    sys.exit(main())
  File "/mnt/petrelfs/zhaoshitian/anaconda3/envs/xlab/lib/python3.10/site-packages/accelerate/commands/accelerate_cli.py", line 48, in main
    args.func(args)
  File "/mnt/petrelfs/zhaoshitian/anaconda3/envs/xlab/lib/python3.10/site-packages/accelerate/commands/launch.py", line 1159, in launch_command
    multi_gpu_launcher(args)
  File "/mnt/petrelfs/zhaoshitian/anaconda3/envs/xlab/lib/python3.10/site-packages/accelerate/commands/launch.py", line 793, in multi_gpu_launcher
    distrib_run.run(args)
  File "/mnt/petrelfs/zhaoshitian/anaconda3/envs/xlab/lib/python3.10/site-packages/torch/distributed/run.py", line 910, in run
    elastic_launch(
  File "/mnt/petrelfs/zhaoshitian/anaconda3/envs/xlab/lib/python3.10/site-packages/torch/distributed/launcher/api.py", line 138, in __call__
    return launch_agent(self._config, self._entrypoint, list(args))
  File "/mnt/petrelfs/zhaoshitian/anaconda3/envs/xlab/lib/python3.10/site-packages/torch/distributed/launcher/api.py", line 269, in launch_agent
    raise ChildFailedError(
torch.distributed.elastic.multiprocessing.errors.ChildFailedError: 
============================================================
train_flux_deepspeed_controlnet.py FAILED
------------------------------------------------------------
Failures:
  <NO_OTHER_FAILURES>
------------------------------------------------------------
Root Cause (first observed failure):
[0]:
  time      : 2024-11-20_15:51:10
  host      : SH-IDC1-10-140-1-48
  rank      : 0 (local_rank: 0)
  exitcode  : 1 (pid: 84443)
  error_file: <N/A>
  traceback : To enable traceback see: https://pytorch.org/docs/stable/elastic/errors.html
============================================================
srun: error: SH-IDC1-10-140-1-48: task 0: Exited with exit code 1
