The following values were not passed to `accelerate launch` and had defaults used instead:
	`--num_processes` was set to a value of `4`
		More than one GPU was found, enabling multi-GPU training.
		If this was unintended please pass in `--num_processes=1`.
	`--num_machines` was set to a value of `1`
	`--mixed_precision` was set to a value of `'no'`
	`--dynamo_backend` was set to a value of `'no'`
To avoid this warning pass in values for each of the problematic parameters or run `accelerate config`.
/mnt/petrelfs/zhaoshitian/anaconda3/envs/xlab/lib/python3.10/site-packages/accelerate/accelerator.py:443: UserWarning: `log_with=wandb` was passed but no supported trackers are currently installed.
  warnings.warn(f"`log_with={log_with}` was passed but no supported trackers are currently installed.")
Detected kernel version 3.10.0, which is below the recommended minimum of 5.5.0; this can cause the process to hang. It is recommended to upgrade the kernel to the minimum version or higher.
11/20/2024 16:45:26 - INFO - __main__ - Distributed environment: MULTI_GPU  Backend: nccl
Num processes: 4
Process index: 0
Local process index: 0
Device: cuda:0

Mixed precision type: bf16

DEVICE cuda:0
/mnt/petrelfs/zhaoshitian/anaconda3/envs/xlab/lib/python3.10/site-packages/accelerate/accelerator.py:443: UserWarning: `log_with=wandb` was passed but no supported trackers are currently installed.
  warnings.warn(f"`log_with={log_with}` was passed but no supported trackers are currently installed.")
/mnt/petrelfs/zhaoshitian/anaconda3/envs/xlab/lib/python3.10/site-packages/accelerate/accelerator.py:443: UserWarning: `log_with=wandb` was passed but no supported trackers are currently installed.
  warnings.warn(f"`log_with={log_with}` was passed but no supported trackers are currently installed.")
11/20/2024 16:45:27 - INFO - __main__ - Distributed environment: MULTI_GPU  Backend: nccl
Num processes: 4
Process index: 1
Local process index: 1
Device: cuda:1

Mixed precision type: bf16

11/20/2024 16:45:27 - INFO - __main__ - Distributed environment: MULTI_GPU  Backend: nccl
Num processes: 4
Process index: 3
Local process index: 3
Device: cuda:3

Mixed precision type: bf16

DEVICE cuda:1
DEVICE cuda:3
/mnt/petrelfs/zhaoshitian/anaconda3/envs/xlab/lib/python3.10/site-packages/accelerate/accelerator.py:443: UserWarning: `log_with=wandb` was passed but no supported trackers are currently installed.
  warnings.warn(f"`log_with={log_with}` was passed but no supported trackers are currently installed.")
11/20/2024 16:45:27 - INFO - __main__ - Distributed environment: MULTI_GPU  Backend: nccl
Num processes: 4
Process index: 2
Local process index: 2
Device: cuda:2

Mixed precision type: bf16

DEVICE cuda:2
Loading checkpoint shards:   0%|          | 0/2 [00:00<?, ?it/s]Loading checkpoint shards:  50%|█████     | 1/2 [00:00<00:00,  4.47it/s]Loading checkpoint shards: 100%|██████████| 2/2 [00:00<00:00,  5.24it/s]Loading checkpoint shards: 100%|██████████| 2/2 [00:00<00:00,  5.11it/s]
Loading checkpoint shards:   0%|          | 0/2 [00:00<?, ?it/s]Loading checkpoint shards:   0%|          | 0/2 [00:00<?, ?it/s]Loading checkpoint shards:   0%|          | 0/2 [00:00<?, ?it/s]Loading checkpoint shards:  50%|█████     | 1/2 [00:00<00:00,  5.34it/s]Loading checkpoint shards:  50%|█████     | 1/2 [00:00<00:00,  4.72it/s]Loading checkpoint shards:  50%|█████     | 1/2 [00:00<00:00,  5.27it/s]Loading checkpoint shards: 100%|██████████| 2/2 [00:00<00:00,  5.98it/s]Loading checkpoint shards: 100%|██████████| 2/2 [00:00<00:00,  5.87it/s]
Loading checkpoint shards: 100%|██████████| 2/2 [00:00<00:00,  5.68it/s]Loading checkpoint shards: 100%|██████████| 2/2 [00:00<00:00,  5.51it/s]
Loading checkpoint shards: 100%|██████████| 2/2 [00:00<00:00,  5.96it/s]Loading checkpoint shards: 100%|██████████| 2/2 [00:00<00:00,  5.84it/s]
Init model
Init model
Init model
Init model
Loading checkpoint
Loading checkpoint
Loading checkpoint
Loading checkpoint
Init AE
Init AE
Init AE
Init AE
[rank2]: Traceback (most recent call last):
[rank2]:   File "/mnt/petrelfs/zhaoshitian/x-flux-forge/train_flux_deepspeed_controlnet.py", line 318, in <module>
[rank2]:     main()
[rank2]:   File "/mnt/petrelfs/zhaoshitian/x-flux-forge/train_flux_deepspeed_controlnet.py", line 104, in main
[rank2]:     dit, vae, t5, clip = get_models(name=args.model_name, device=accelerator.device, offload=False, is_schnell=is_schnell)
[rank2]:   File "/mnt/petrelfs/zhaoshitian/x-flux-forge/train_flux_deepspeed_controlnet.py", line 51, in get_models
[rank2]:     vae = load_ae(name, device="cpu" if offload else device)
[rank2]:   File "/mnt/petrelfs/zhaoshitian/x-flux-forge/src/flux/util.py", line 389, in load_ae
[rank2]:     sd = load_sft(ckpt_path, device=str(device))
[rank2]:   File "/mnt/petrelfs/zhaoshitian/anaconda3/envs/xlab/lib/python3.10/site-packages/safetensors/torch.py", line 315, in load_file
[rank2]:     result[k] = f.get_tensor(k)
[rank2]: torch.OutOfMemoryError: CUDA out of memory. Tried to allocate 2.00 MiB. GPU 2 has a total capacity of 79.32 GiB of which 1.56 MiB is free. Process 219736 has 69.17 GiB memory in use. Including non-PyTorch memory, this process has 10.15 GiB memory in use. Of the allocated memory 9.15 GiB is allocated by PyTorch, and 15.24 MiB is reserved by PyTorch but unallocated. If reserved but unallocated memory is large try setting PYTORCH_CUDA_ALLOC_CONF=expandable_segments:True to avoid fragmentation.  See documentation for Memory Management  (https://pytorch.org/docs/stable/notes/cuda.html#environment-variables)
W1120 16:45:47.193626 517266 site-packages/torch/distributed/elastic/multiprocessing/api.py:897] Sending process 517468 closing signal SIGTERM
W1120 16:45:47.266885 517266 site-packages/torch/distributed/elastic/multiprocessing/api.py:897] Sending process 517469 closing signal SIGTERM
W1120 16:45:47.270090 517266 site-packages/torch/distributed/elastic/multiprocessing/api.py:897] Sending process 517471 closing signal SIGTERM
E1120 16:45:47.785712 517266 site-packages/torch/distributed/elastic/multiprocessing/api.py:869] failed (exitcode: 1) local_rank: 2 (pid: 517470) of binary: /mnt/petrelfs/zhaoshitian/anaconda3/envs/xlab/bin/python
Traceback (most recent call last):
  File "/mnt/petrelfs/zhaoshitian/anaconda3/envs/xlab/bin/accelerate", line 8, in <module>
    sys.exit(main())
  File "/mnt/petrelfs/zhaoshitian/anaconda3/envs/xlab/lib/python3.10/site-packages/accelerate/commands/accelerate_cli.py", line 48, in main
    args.func(args)
  File "/mnt/petrelfs/zhaoshitian/anaconda3/envs/xlab/lib/python3.10/site-packages/accelerate/commands/launch.py", line 1159, in launch_command
    multi_gpu_launcher(args)
  File "/mnt/petrelfs/zhaoshitian/anaconda3/envs/xlab/lib/python3.10/site-packages/accelerate/commands/launch.py", line 793, in multi_gpu_launcher
    distrib_run.run(args)
  File "/mnt/petrelfs/zhaoshitian/anaconda3/envs/xlab/lib/python3.10/site-packages/torch/distributed/run.py", line 910, in run
    elastic_launch(
  File "/mnt/petrelfs/zhaoshitian/anaconda3/envs/xlab/lib/python3.10/site-packages/torch/distributed/launcher/api.py", line 138, in __call__
    return launch_agent(self._config, self._entrypoint, list(args))
  File "/mnt/petrelfs/zhaoshitian/anaconda3/envs/xlab/lib/python3.10/site-packages/torch/distributed/launcher/api.py", line 269, in launch_agent
    raise ChildFailedError(
torch.distributed.elastic.multiprocessing.errors.ChildFailedError: 
============================================================
train_flux_deepspeed_controlnet.py FAILED
------------------------------------------------------------
Failures:
  <NO_OTHER_FAILURES>
------------------------------------------------------------
Root Cause (first observed failure):
[0]:
  time      : 2024-11-20_16:45:47
  host      : SH-IDC1-10-140-1-100
  rank      : 2 (local_rank: 2)
  exitcode  : 1 (pid: 517470)
  error_file: <N/A>
  traceback : To enable traceback see: https://pytorch.org/docs/stable/elastic/errors.html
============================================================
srun: error: SH-IDC1-10-140-1-100: task 0: Exited with exit code 1
