The following values were not passed to `accelerate launch` and had defaults used instead:
	`--num_processes` was set to a value of `4`
		More than one GPU was found, enabling multi-GPU training.
		If this was unintended please pass in `--num_processes=1`.
	`--num_machines` was set to a value of `1`
	`--mixed_precision` was set to a value of `'no'`
	`--dynamo_backend` was set to a value of `'no'`
To avoid this warning pass in values for each of the problematic parameters or run `accelerate config`.
/mnt/petrelfs/zhaoshitian/anaconda3/envs/xlab/lib/python3.10/site-packages/accelerate/accelerator.py:443: UserWarning: `log_with=wandb` was passed but no supported trackers are currently installed.
  warnings.warn(f"`log_with={log_with}` was passed but no supported trackers are currently installed.")
Detected kernel version 3.10.0, which is below the recommended minimum of 5.5.0; this can cause the process to hang. It is recommended to upgrade the kernel to the minimum version or higher.
11/20/2024 19:22:05 - INFO - __main__ - Distributed environment: MULTI_GPU  Backend: nccl
Num processes: 4
Process index: 0
Local process index: 0
Device: cuda:0

Mixed precision type: bf16

DEVICE cuda:0
DEVICE cuda:3
/mnt/petrelfs/zhaoshitian/anaconda3/envs/xlab/lib/python3.10/site-packages/accelerate/accelerator.py:443: UserWarning: `log_with=wandb` was passed but no supported trackers are currently installed.
  warnings.warn(f"`log_with={log_with}` was passed but no supported trackers are currently installed.")
11/20/2024 19:22:11 - INFO - __main__ - Distributed environment: MULTI_GPU  Backend: nccl
Num processes: 4
Process index: 3
Local process index: 3
Device: cuda:3

Mixed precision type: bf16

/mnt/petrelfs/zhaoshitian/anaconda3/envs/xlab/lib/python3.10/site-packages/accelerate/accelerator.py:443: UserWarning: `log_with=wandb` was passed but no supported trackers are currently installed.
  warnings.warn(f"`log_with={log_with}` was passed but no supported trackers are currently installed.")
11/20/2024 19:22:11 - INFO - __main__ - Distributed environment: MULTI_GPU  Backend: nccl
Num processes: 4
Process index: 1
Local process index: 1
Device: cuda:1

Mixed precision type: bf16

DEVICE cuda:1
/mnt/petrelfs/zhaoshitian/anaconda3/envs/xlab/lib/python3.10/site-packages/accelerate/accelerator.py:443: UserWarning: `log_with=wandb` was passed but no supported trackers are currently installed.
  warnings.warn(f"`log_with={log_with}` was passed but no supported trackers are currently installed.")
11/20/2024 19:22:12 - INFO - __main__ - Distributed environment: MULTI_GPU  Backend: nccl
Num processes: 4
Process index: 2
Local process index: 2
Device: cuda:2

Mixed precision type: bf16

DEVICE cuda:2
Loading checkpoint shards:   0%|          | 0/2 [00:00<?, ?it/s]Loading checkpoint shards:  50%|█████     | 1/2 [00:01<00:01,  1.31s/it]Loading checkpoint shards: 100%|██████████| 2/2 [00:01<00:00,  1.07it/s]Loading checkpoint shards: 100%|██████████| 2/2 [00:01<00:00,  1.01it/s]
Loading checkpoint shards:   0%|          | 0/2 [00:00<?, ?it/s]Loading checkpoint shards:  50%|█████     | 1/2 [00:00<00:00,  1.52it/s]Loading checkpoint shards: 100%|██████████| 2/2 [00:01<00:00,  1.43it/s]Loading checkpoint shards: 100%|██████████| 2/2 [00:01<00:00,  1.44it/s]
Loading checkpoint shards:   0%|          | 0/2 [00:00<?, ?it/s]Loading checkpoint shards:   0%|          | 0/2 [00:00<?, ?it/s]Loading checkpoint shards:  50%|█████     | 1/2 [00:01<00:01,  1.34s/it]Loading checkpoint shards: 100%|██████████| 2/2 [00:01<00:00,  1.12it/s]Loading checkpoint shards: 100%|██████████| 2/2 [00:01<00:00,  1.04it/s]
Loading checkpoint shards:  50%|█████     | 1/2 [00:00<00:00,  1.10it/s]Loading checkpoint shards: 100%|██████████| 2/2 [00:02<00:00,  1.04s/it]Loading checkpoint shards: 100%|██████████| 2/2 [00:02<00:00,  1.03s/it]
Init model
Loading checkpoint
Init AE
Init model
Loading checkpoint
Init AE
Init model
Loading checkpoint
Init AE
Init model
Loading checkpoint
Init AE
[rank0]: Traceback (most recent call last):
[rank0]:   File "/mnt/petrelfs/zhaoshitian/x-flux-forge/train_flux_deepspeed_controlnet.py", line 318, in <module>
[rank0]:     main()
[rank0]:   File "/mnt/petrelfs/zhaoshitian/x-flux-forge/train_flux_deepspeed_controlnet.py", line 110, in main
[rank0]:     dit.to(accelerator.device)
[rank0]:   File "/mnt/petrelfs/zhaoshitian/anaconda3/envs/xlab/lib/python3.10/site-packages/torch/nn/modules/module.py", line 1340, in to
[rank0]:     return self._apply(convert)
[rank0]:   File "/mnt/petrelfs/zhaoshitian/anaconda3/envs/xlab/lib/python3.10/site-packages/torch/nn/modules/module.py", line 900, in _apply
[rank0]:     module._apply(fn)
[rank0]:   File "/mnt/petrelfs/zhaoshitian/anaconda3/envs/xlab/lib/python3.10/site-packages/torch/nn/modules/module.py", line 900, in _apply
[rank0]:     module._apply(fn)
[rank0]:   File "/mnt/petrelfs/zhaoshitian/anaconda3/envs/xlab/lib/python3.10/site-packages/torch/nn/modules/module.py", line 900, in _apply
[rank0]:     module._apply(fn)
[rank0]:   File "/mnt/petrelfs/zhaoshitian/anaconda3/envs/xlab/lib/python3.10/site-packages/torch/nn/modules/module.py", line 927, in _apply
[rank0]:     param_applied = fn(param)
[rank0]:   File "/mnt/petrelfs/zhaoshitian/anaconda3/envs/xlab/lib/python3.10/site-packages/torch/nn/modules/module.py", line 1326, in convert
[rank0]:     return t.to(
[rank0]: torch.OutOfMemoryError: CUDA out of memory. Tried to allocate 90.00 MiB. GPU 0 has a total capacity of 79.32 GiB of which 43.56 MiB is free. Process 222173 has 53.96 GiB memory in use. Including non-PyTorch memory, this process has 25.32 GiB memory in use. Of the allocated memory 24.29 GiB is allocated by PyTorch, and 39.78 MiB is reserved by PyTorch but unallocated. If reserved but unallocated memory is large try setting PYTORCH_CUDA_ALLOC_CONF=expandable_segments:True to avoid fragmentation.  See documentation for Memory Management  (https://pytorch.org/docs/stable/notes/cuda.html#environment-variables)
[rank0]:[W1120 19:23:02.297043013 ProcessGroupNCCL.cpp:1250] Warning: WARNING: process group has NOT been destroyed before we destruct ProcessGroupNCCL. On normal program exit, the application should call destroy_process_group to ensure that any pending NCCL operations have finished in this process. In rare cases this process can exit before this point and block the progress of another member of the process group. This constraint has always been present,  but this warning has only been added since PyTorch 2.4 (function operator())
W1120 19:23:06.576645 439938 site-packages/torch/distributed/elastic/multiprocessing/api.py:897] Sending process 443086 closing signal SIGTERM
W1120 19:23:06.594453 439938 site-packages/torch/distributed/elastic/multiprocessing/api.py:897] Sending process 443091 closing signal SIGTERM
W1120 19:23:06.597419 439938 site-packages/torch/distributed/elastic/multiprocessing/api.py:897] Sending process 443096 closing signal SIGTERM
E1120 19:23:10.221800 439938 site-packages/torch/distributed/elastic/multiprocessing/api.py:869] failed (exitcode: 1) local_rank: 0 (pid: 443076) of binary: /mnt/petrelfs/zhaoshitian/anaconda3/envs/xlab/bin/python
Traceback (most recent call last):
  File "/mnt/petrelfs/zhaoshitian/anaconda3/envs/xlab/bin/accelerate", line 8, in <module>
    sys.exit(main())
  File "/mnt/petrelfs/zhaoshitian/anaconda3/envs/xlab/lib/python3.10/site-packages/accelerate/commands/accelerate_cli.py", line 48, in main
    args.func(args)
  File "/mnt/petrelfs/zhaoshitian/anaconda3/envs/xlab/lib/python3.10/site-packages/accelerate/commands/launch.py", line 1159, in launch_command
    multi_gpu_launcher(args)
  File "/mnt/petrelfs/zhaoshitian/anaconda3/envs/xlab/lib/python3.10/site-packages/accelerate/commands/launch.py", line 793, in multi_gpu_launcher
    distrib_run.run(args)
  File "/mnt/petrelfs/zhaoshitian/anaconda3/envs/xlab/lib/python3.10/site-packages/torch/distributed/run.py", line 910, in run
    elastic_launch(
  File "/mnt/petrelfs/zhaoshitian/anaconda3/envs/xlab/lib/python3.10/site-packages/torch/distributed/launcher/api.py", line 138, in __call__
    return launch_agent(self._config, self._entrypoint, list(args))
  File "/mnt/petrelfs/zhaoshitian/anaconda3/envs/xlab/lib/python3.10/site-packages/torch/distributed/launcher/api.py", line 269, in launch_agent
    raise ChildFailedError(
torch.distributed.elastic.multiprocessing.errors.ChildFailedError: 
============================================================
train_flux_deepspeed_controlnet.py FAILED
------------------------------------------------------------
Failures:
  <NO_OTHER_FAILURES>
------------------------------------------------------------
Root Cause (first observed failure):
[0]:
  time      : 2024-11-20_19:23:06
  host      : SH-IDC1-10-140-0-135
  rank      : 0 (local_rank: 0)
  exitcode  : 1 (pid: 443076)
  error_file: <N/A>
  traceback : To enable traceback see: https://pytorch.org/docs/stable/elastic/errors.html
============================================================
srun: error: SH-IDC1-10-140-0-135: task 0: Exited with exit code 1
