The following values were not passed to `accelerate launch` and had defaults used instead:
	`--num_processes` was set to a value of `4`
		More than one GPU was found, enabling multi-GPU training.
		If this was unintended please pass in `--num_processes=1`.
	`--num_machines` was set to a value of `1`
	`--mixed_precision` was set to a value of `'no'`
	`--dynamo_backend` was set to a value of `'no'`
To avoid this warning pass in values for each of the problematic parameters or run `accelerate config`.
/mnt/petrelfs/zhaoshitian/anaconda3/envs/xlab/lib/python3.10/site-packages/accelerate/accelerator.py:443: UserWarning: `log_with=wandb` was passed but no supported trackers are currently installed.
  warnings.warn(f"`log_with={log_with}` was passed but no supported trackers are currently installed.")
Detected kernel version 3.10.0, which is below the recommended minimum of 5.5.0; this can cause the process to hang. It is recommended to upgrade the kernel to the minimum version or higher.
11/19/2024 19:30:28 - INFO - __main__ - Distributed environment: MULTI_GPU  Backend: nccl
Num processes: 4
Process index: 0
Local process index: 0
Device: cuda:0

Mixed precision type: bf16

DEVICE cuda:0
/mnt/petrelfs/zhaoshitian/anaconda3/envs/xlab/lib/python3.10/site-packages/accelerate/accelerator.py:443: UserWarning: `log_with=wandb` was passed but no supported trackers are currently installed.
  warnings.warn(f"`log_with={log_with}` was passed but no supported trackers are currently installed.")
11/19/2024 19:30:29 - INFO - __main__ - Distributed environment: MULTI_GPU  Backend: nccl
Num processes: 4
Process index: 2
Local process index: 2
Device: cuda:2

Mixed precision type: bf16

DEVICE cuda:2
/mnt/petrelfs/zhaoshitian/anaconda3/envs/xlab/lib/python3.10/site-packages/accelerate/accelerator.py:443: UserWarning: `log_with=wandb` was passed but no supported trackers are currently installed.
  warnings.warn(f"`log_with={log_with}` was passed but no supported trackers are currently installed.")
11/19/2024 19:30:29 - INFO - __main__ - Distributed environment: MULTI_GPU  Backend: nccl
Num processes: 4
Process index: 3
Local process index: 3
Device: cuda:3

Mixed precision type: bf16

DEVICE cuda:3
/mnt/petrelfs/zhaoshitian/anaconda3/envs/xlab/lib/python3.10/site-packages/accelerate/accelerator.py:443: UserWarning: `log_with=wandb` was passed but no supported trackers are currently installed.
  warnings.warn(f"`log_with={log_with}` was passed but no supported trackers are currently installed.")
11/19/2024 19:30:29 - INFO - __main__ - Distributed environment: MULTI_GPU  Backend: nccl
Num processes: 4
Process index: 1
Local process index: 1
Device: cuda:1

Mixed precision type: bf16

DEVICE cuda:1
Downloading shards:   0%|          | 0/2 [00:00<?, ?it/s]Downloading shards:   0%|          | 0/2 [00:00<?, ?it/s]Downloading shards:   0%|          | 0/2 [00:00<?, ?it/s]Downloading shards:   0%|          | 0/2 [00:00<?, ?it/s]Downloading shards:  50%|█████     | 1/2 [27:39<27:39, 1659.93s/it]Downloading shards: 100%|██████████| 2/2 [56:19<00:00, 1694.76s/it]Downloading shards: 100%|██████████| 2/2 [56:19<00:00, 1689.53s/it]
Loading checkpoint shards:   0%|          | 0/2 [00:00<?, ?it/s]Loading checkpoint shards:   0%|          | 0/2 [00:00<?, ?it/s]
[rank0]: Traceback (most recent call last):
[rank0]:   File "/mnt/petrelfs/zhaoshitian/x-flux-forge/train_flux_deepspeed_controlnet.py", line 317, in <module>
[rank0]:     main()
[rank0]:   File "/mnt/petrelfs/zhaoshitian/x-flux-forge/train_flux_deepspeed_controlnet.py", line 103, in main
[rank0]:     dit, vae, t5, clip = get_models(name=args.model_name, device=accelerator.device, offload=False, is_schnell=is_schnell)
[rank0]:   File "/mnt/petrelfs/zhaoshitian/x-flux-forge/train_flux_deepspeed_controlnet.py", line 47, in get_models
[rank0]:     t5 = load_t5(device, max_length=256 if is_schnell else 512)
[rank0]:   File "/mnt/petrelfs/zhaoshitian/x-flux-forge/src/flux/util.py", line 365, in load_t5
[rank0]:     return HFEmbedder("xlabs-ai/xflux_text_encoders", max_length=max_length, torch_dtype=torch.bfloat16, force_download=True).to(device)
[rank0]:   File "/mnt/petrelfs/zhaoshitian/x-flux-forge/src/flux/modules/conditioner.py", line 18, in __init__
[rank0]:     self.hf_module: T5EncoderModel = T5EncoderModel.from_pretrained(version, **hf_kwargs)
[rank0]:   File "/mnt/petrelfs/zhaoshitian/anaconda3/envs/xlab/lib/python3.10/site-packages/transformers/modeling_utils.py", line 4225, in from_pretrained
[rank0]:     ) = cls._load_pretrained_model(
[rank0]:   File "/mnt/petrelfs/zhaoshitian/anaconda3/envs/xlab/lib/python3.10/site-packages/transformers/modeling_utils.py", line 4706, in _load_pretrained_model
[rank0]:     state_dict = load_state_dict(
[rank0]:   File "/mnt/petrelfs/zhaoshitian/anaconda3/envs/xlab/lib/python3.10/site-packages/transformers/modeling_utils.py", line 555, in load_state_dict
[rank0]:     with safe_open(checkpoint_file, framework="pt") as f:
[rank0]: safetensors_rust.SafetensorError: Error while deserializing header: MetadataIncompleteBuffer
[rank0]:[W1119 20:27:00.960579135 ProcessGroupNCCL.cpp:1250] Warning: WARNING: process group has NOT been destroyed before we destruct ProcessGroupNCCL. On normal program exit, the application should call destroy_process_group to ensure that any pending NCCL operations have finished in this process. In rare cases this process can exit before this point and block the progress of another member of the process group. This constraint has always been present,  but this warning has only been added since PyTorch 2.4 (function operator())
W1119 20:27:01.160471 55608 site-packages/torch/distributed/elastic/multiprocessing/api.py:897] Sending process 63763 closing signal SIGTERM
W1119 20:27:01.164576 55608 site-packages/torch/distributed/elastic/multiprocessing/api.py:897] Sending process 63764 closing signal SIGTERM
W1119 20:27:01.165458 55608 site-packages/torch/distributed/elastic/multiprocessing/api.py:897] Sending process 63765 closing signal SIGTERM
E1119 20:27:01.745409 55608 site-packages/torch/distributed/elastic/multiprocessing/api.py:869] failed (exitcode: 1) local_rank: 0 (pid: 63757) of binary: /mnt/petrelfs/zhaoshitian/anaconda3/envs/xlab/bin/python
Traceback (most recent call last):
  File "/mnt/petrelfs/zhaoshitian/anaconda3/envs/xlab/bin/accelerate", line 8, in <module>
    sys.exit(main())
  File "/mnt/petrelfs/zhaoshitian/anaconda3/envs/xlab/lib/python3.10/site-packages/accelerate/commands/accelerate_cli.py", line 48, in main
    args.func(args)
  File "/mnt/petrelfs/zhaoshitian/anaconda3/envs/xlab/lib/python3.10/site-packages/accelerate/commands/launch.py", line 1159, in launch_command
    multi_gpu_launcher(args)
  File "/mnt/petrelfs/zhaoshitian/anaconda3/envs/xlab/lib/python3.10/site-packages/accelerate/commands/launch.py", line 793, in multi_gpu_launcher
    distrib_run.run(args)
  File "/mnt/petrelfs/zhaoshitian/anaconda3/envs/xlab/lib/python3.10/site-packages/torch/distributed/run.py", line 910, in run
    elastic_launch(
  File "/mnt/petrelfs/zhaoshitian/anaconda3/envs/xlab/lib/python3.10/site-packages/torch/distributed/launcher/api.py", line 138, in __call__
    return launch_agent(self._config, self._entrypoint, list(args))
  File "/mnt/petrelfs/zhaoshitian/anaconda3/envs/xlab/lib/python3.10/site-packages/torch/distributed/launcher/api.py", line 269, in launch_agent
    raise ChildFailedError(
torch.distributed.elastic.multiprocessing.errors.ChildFailedError: 
============================================================
train_flux_deepspeed_controlnet.py FAILED
------------------------------------------------------------
Failures:
  <NO_OTHER_FAILURES>
------------------------------------------------------------
Root Cause (first observed failure):
[0]:
  time      : 2024-11-19_20:27:01
  host      : SH-IDC1-10-140-1-91
  rank      : 0 (local_rank: 0)
  exitcode  : 1 (pid: 63757)
  error_file: <N/A>
  traceback : To enable traceback see: https://pytorch.org/docs/stable/elastic/errors.html
============================================================
srun: error: SH-IDC1-10-140-1-91: task 0: Exited with exit code 1
