The following values were not passed to `accelerate launch` and had defaults used instead:
	`--num_processes` was set to a value of `4`
		More than one GPU was found, enabling multi-GPU training.
		If this was unintended please pass in `--num_processes=1`.
	`--num_machines` was set to a value of `1`
	`--mixed_precision` was set to a value of `'no'`
	`--dynamo_backend` was set to a value of `'no'`
To avoid this warning pass in values for each of the problematic parameters or run `accelerate config`.
/mnt/petrelfs/zhaoshitian/anaconda3/envs/xlab/lib/python3.10/site-packages/accelerate/accelerator.py:443: UserWarning: `log_with=wandb` was passed but no supported trackers are currently installed.
  warnings.warn(f"`log_with={log_with}` was passed but no supported trackers are currently installed.")
Detected kernel version 3.10.0, which is below the recommended minimum of 5.5.0; this can cause the process to hang. It is recommended to upgrade the kernel to the minimum version or higher.
11/19/2024 19:00:12 - INFO - __main__ - Distributed environment: MULTI_GPU  Backend: nccl
Num processes: 4
Process index: 0
Local process index: 0
Device: cuda:0

Mixed precision type: bf16

DEVICE cuda:0
/mnt/petrelfs/zhaoshitian/anaconda3/envs/xlab/lib/python3.10/site-packages/accelerate/accelerator.py:443: UserWarning: `log_with=wandb` was passed but no supported trackers are currently installed.
  warnings.warn(f"`log_with={log_with}` was passed but no supported trackers are currently installed.")
11/19/2024 19:00:13 - INFO - __main__ - Distributed environment: MULTI_GPU  Backend: nccl
Num processes: 4
Process index: 2
Local process index: 2
Device: cuda:2

Mixed precision type: bf16

DEVICE cuda:2
/mnt/petrelfs/zhaoshitian/anaconda3/envs/xlab/lib/python3.10/site-packages/accelerate/accelerator.py:443: UserWarning: `log_with=wandb` was passed but no supported trackers are currently installed.
  warnings.warn(f"`log_with={log_with}` was passed but no supported trackers are currently installed.")
11/19/2024 19:00:13 - INFO - __main__ - Distributed environment: MULTI_GPU  Backend: nccl
Num processes: 4
Process index: 3
Local process index: 3
Device: cuda:3

Mixed precision type: bf16

DEVICE cuda:3
/mnt/petrelfs/zhaoshitian/anaconda3/envs/xlab/lib/python3.10/site-packages/accelerate/accelerator.py:443: UserWarning: `log_with=wandb` was passed but no supported trackers are currently installed.
  warnings.warn(f"`log_with={log_with}` was passed but no supported trackers are currently installed.")
11/19/2024 19:00:13 - INFO - __main__ - Distributed environment: MULTI_GPU  Backend: nccl
Num processes: 4
Process index: 1
Local process index: 1
Device: cuda:1

Mixed precision type: bf16

DEVICE cuda:1
Downloading shards:   0%|          | 0/2 [00:00<?, ?it/s]Downloading shards:   0%|          | 0/2 [00:00<?, ?it/s]Downloading shards:   0%|          | 0/2 [00:00<?, ?it/s]Downloading shards:   0%|          | 0/2 [00:00<?, ?it/s]slurmstepd: error: *** STEP 16571351.0 ON SH-IDC1-10-140-1-90 CANCELLED AT 2024-11-19T19:00:38 ***
W1119 19:00:38.599440 282856 site-packages/torch/distributed/elastic/agent/server/api.py:704] Received Signals.SIGTERM death signal, shutting down workers
W1119 19:00:38.602049 282856 site-packages/torch/distributed/elastic/multiprocessing/api.py:897] Sending process 282936 closing signal SIGTERM
W1119 19:00:38.602722 282856 site-packages/torch/distributed/elastic/multiprocessing/api.py:897] Sending process 282937 closing signal SIGTERM
W1119 19:00:38.603206 282856 site-packages/torch/distributed/elastic/multiprocessing/api.py:897] Sending process 282938 closing signal SIGTERM
W1119 19:00:38.603628 282856 site-packages/torch/distributed/elastic/multiprocessing/api.py:897] Sending process 282939 closing signal SIGTERM
Traceback (most recent call last):
  File "/mnt/petrelfs/zhaoshitian/anaconda3/envs/xlab/bin/accelerate", line 8, in <module>
    sys.exit(main())
  File "/mnt/petrelfs/zhaoshitian/anaconda3/envs/xlab/lib/python3.10/site-packages/accelerate/commands/accelerate_cli.py", line 48, in main
    args.func(args)
  File "/mnt/petrelfs/zhaoshitian/anaconda3/envs/xlab/lib/python3.10/site-packages/accelerate/commands/launch.py", line 1159, in launch_command
    multi_gpu_launcher(args)
  File "/mnt/petrelfs/zhaoshitian/anaconda3/envs/xlab/lib/python3.10/site-packages/accelerate/commands/launch.py", line 793, in multi_gpu_launcher
    distrib_run.run(args)
  File "/mnt/petrelfs/zhaoshitian/anaconda3/envs/xlab/lib/python3.10/site-packages/torch/distributed/run.py", line 910, in run
    elastic_launch(
  File "/mnt/petrelfs/zhaoshitian/anaconda3/envs/xlab/lib/python3.10/site-packages/torch/distributed/launcher/api.py", line 138, in __call__
    return launch_agent(self._config, self._entrypoint, list(args))
  File "/mnt/petrelfs/zhaoshitian/anaconda3/envs/xlab/lib/python3.10/site-packages/torch/distributed/launcher/api.py", line 260, in launch_agent
    result = agent.run()
  File "/mnt/petrelfs/zhaoshitian/anaconda3/envs/xlab/lib/python3.10/site-packages/torch/distributed/elastic/metrics/api.py", line 137, in wrapper
    result = f(*args, **kwargs)
  File "/mnt/petrelfs/zhaoshitian/anaconda3/envs/xlab/lib/python3.10/site-packages/torch/distributed/elastic/agent/server/api.py", line 696, in run
    result = self._invoke_run(role)
  File "/mnt/petrelfs/zhaoshitian/anaconda3/envs/xlab/lib/python3.10/site-packages/torch/distributed/elastic/agent/server/api.py", line 855, in _invoke_run
    time.sleep(monitor_interval)
  File "/mnt/petrelfs/zhaoshitian/anaconda3/envs/xlab/lib/python3.10/site-packages/torch/distributed/elastic/multiprocessing/api.py", line 84, in _terminate_process_handler
    raise SignalException(f"Process {os.getpid()} got signal: {sigval}", sigval=sigval)
torch.distributed.elastic.multiprocessing.api.SignalException: Process 282856 got signal: 15
srun: error: SH-IDC1-10-140-1-90: task 0: Exited with exit code 1
